#VRML_SIM R2021a utf8
WorldInfo {
  info [
    "Arena for Stage 1 of SLRC2021 University Category"
  ]
  title "SLRC2021 UniS1"
  coordinateSystem "NUE"
}
Viewpoint {
  orientation 1 0 0 4.71238898038469
  position -0.0850002450120716 7.197528396184857 0.7400333236496849
}
DirectionalLight {
  direction 0 -1 0
}
DirectionalLight {
  direction -1 -1 0
}
DirectionalLight {
  direction 0 -1 -1
}
DirectionalLight {
  direction 1 -1 0
}
DirectionalLight {
  direction 0 -1 1
}
RectangleArena {
  name "Floor_black"
  floorSize 3 4
  floorTileSize 2 2
  floorAppearance Parquetry {
    type "dark strip"
    colorOverride 0 0 0
  }
  wallAppearance DEF Wall_white PBRAppearance {
    roughness 0.2
    metalness 0
    name "Wall_white"
  }
}
DEF Line Solid {
  translation -0.613 -0.00485 -1.5
  scale 0.01 0.01 0.01
  children [
    Shape {
      appearance PBRAppearance {
        roughness 1
        metalness 0
      }
      geometry Mesh {
        url [
          "../solidworks/Lines.STL"
        ]
      }
      castShadows FALSE
      isPickable FALSE
    }
  ]
  name "White_lines"
  locked TRUE
  translationStep 0
  rotationStep 0
}
DEF Squares Group {
  children [
    DEF Patch Solid {
      translation -0.075 -0.00484 1.1
      scale 0.01 0.01 0.01
      children [
        Shape {
          appearance PBRAppearance {
            baseColor 1 0 0
            roughness 1
            metalness 0
          }
          geometry Mesh {
            url [
              "../solidworks/Square.STL"
            ]
          }
          castShadows FALSE
          isPickable FALSE
        }
      ]
      name "color_patch"
      locked TRUE
      translationStep 0
      rotationStep 0
    }
    DEF Green Solid {
      translation 0.01 -0.00484 -1.65
      scale 0.01 0.01 0.01
      children [
        Shape {
          appearance PBRAppearance {
            baseColor 0 1 0
            roughness 1
            metalness 0
          }
          geometry Mesh {
            url [
              "../solidworks/Square.STL"
            ]
          }
          castShadows FALSE
          isPickable FALSE
        }
      ]
      name "green_square"
      locked TRUE
      translationStep 0
      rotationStep 0
    }
    DEF Red Solid {
      translation -0.41 -0.00484 -1.65
      scale 0.01 0.01 0.01
      children [
        Shape {
          appearance PBRAppearance {
            baseColor 1 0 0
            roughness 1
            metalness 0
          }
          geometry Mesh {
            url [
              "../solidworks/Square.STL"
            ]
          }
          castShadows FALSE
          isPickable FALSE
        }
      ]
      name "red_square"
      locked TRUE
      translationStep 0
      rotationStep 0
    }
    DEF Blue Solid {
      translation 0.43 -0.00484 -1.65
      scale 0.01 0.01 0.01
      children [
        Shape {
          appearance PBRAppearance {
            baseColor 0 0 1
            roughness 1
            metalness 0
          }
          geometry Mesh {
            url [
              "../solidworks/Square.STL"
            ]
          }
          castShadows FALSE
          isPickable FALSE
        }
      ]
      name "blue_square"
      locked TRUE
      translationStep 0
      rotationStep 0
    }
  ]
}
DEF Inner_wall Solid {
  translation 0.19 0 -0.66
  scale 0.01 0.01 0.01
  children [
    DEF Inner_wall Shape {
      appearance USE Wall_white
      geometry Mesh {
        url [
          "../solidworks/Inner_walls.STL"
        ]
      }
    }
  ]
  name "Inner_walls"
  boundingObject USE Inner_wall
  locked TRUE
  recognitionColors [
    1 1 1
  ]
  translationStep 0
  rotationStep 0
}
DEF Right_pillar Solid {
  translation 0.125 0.02 0.74
  children [
    Shape {
      appearance PBRAppearance {
        roughness 0.2
        metalness 0
      }
      geometry Box {
        size 0.02 0.04 0.12
      }
    }
  ]
  name "R_pillar"
  radarCrossSection 1
}
DEF Left_pillar Solid {
  translation -0.125 0.04 0.74
  children [
    Shape {
      appearance PBRAppearance {
        roughness 0.2
        metalness 0
      }
      geometry Box {
        size 0.02 0.09 0.12
      }
    }
  ]
  name "L_pillar"
  radarCrossSection 1
}
DEF v1_5 Robot {
  translation 0.00566726 0.06 1.63305
  rotation 0 1 0 3.14158
  children [
    DEF body Shape {
      appearance PBRAppearance {
        baseColor 0 0.2 0.2
        roughness 1
        metalness 0
      }
      geometry Cylinder {
        height 0.08
        radius 0.05
      }
    }
    DEF right_wheel HingeJoint {
      jointParameters HingeJointParameters {
        anchor -0.055 -0.03 0
      }
      device [
        PositionSensor {
          name "rightencorder"
        }
        RotationalMotor {
          name "rightMotor"
        }
      ]
      endPoint Solid {
        translation -0.055 -0.03 0
        rotation 0.003655940068846235 -0.0036531269743638154 -0.9999866442935735 4.713172275302292
        children [
          DEF wheel Shape {
            appearance PBRAppearance {
              baseColor 0.3 0.2 0
              roughness 1
              metalness 0
            }
            geometry Cylinder {
              height 0.01
              radius 0.03
            }
          }
        ]
        name "solid1"
        boundingObject USE wheel
        physics Physics {
        }
      }
    }
    DEF left_wheel HingeJoint {
      jointParameters HingeJointParameters {
        anchor 0.055 -0.03 0
      }
      device [
        RotationalMotor {
          name "leftMotor"
        }
        PositionSensor {
          name "leftencorder"
        }
      ]
      endPoint Solid {
        translation 0.055 -0.03 0
        rotation 0.0036559401154854375 -0.003653126982309806 -0.9999866442933742 4.713172275361375
        children [
          USE wheel
        ]
        boundingObject USE wheel
        physics Physics {
        }
      }
    }
    DEF Front_caster Transform {
      translation 0 -0.03 0.04
      children [
        Solid {
          translation 0 -0.02 0
          children [
            DEF caster Shape {
              appearance PBRAppearance {
                baseColor 0.2 0.2 0.3
                metalness 0
              }
              geometry Sphere {
                radius 0.01
                subdivision 4
              }
            }
          ]
          name "solid(1)"
          boundingObject USE caster
          physics Physics {
          }
        }
      ]
    }
    DEF Back_caster Transform {
      translation 0 -0.03 -0.04
      children [
        Solid {
          translation 0 -0.02 0
          children [
            DEF caster Shape {
              appearance PBRAppearance {
                baseColor 0.2 0.2 0.3
              }
              geometry Sphere {
                radius 0.01
                subdivision 4
              }
            }
          ]
          name "solid(2)"
          boundingObject USE caster
          physics Physics {
          }
        }
      ]
    }
    DEF Distance_sensors Transform {
      translation 0 -0.035 0.0525
      children [
        SliderJoint {
          jointParameters JointParameters {
            axis 0 1 0
          }
          device [
            LinearMotor {
              name "ds_slider"
            }
          ]
          endPoint Solid {
            children [
              DistanceSensor {
                translation -0.06 0 0
                rotation 0 1 0 3.14159
                name "ds_right"
                lookupTable [
                  0 0 0
                  0.17 1564 0
                ]
                type "infra-red"
              }
              DistanceSensor {
                translation 0.06 0 0
                name "ds_left"
                lookupTable [
                  0 0 0
                  0.17 1564 0
                ]
                type "infra-red"
              }
              DistanceSensor {
                translation 0 0 0.0025
                rotation 0 1 0 -1.5707953071795862
                name "ds_front"
                lookupTable [
                  0 0 0
                  0.07 644 0
                ]
                type "infra-red"
              }
            ]
            name "solid(4)"
          }
        }
        Shape {
          appearance PBRAppearance {
            baseColor 0 0 0.1
            roughness 1
            metalness 0
          }
          geometry Box {
            size 0.12 0.01 0.005
          }
        }
      ]
    }
    DEF Camera_slider Transform {
      translation 0 0.005 0.0525
      children [
        Shape {
          appearance PBRAppearance {
            baseColor 0 0 0.1
            roughness 1
            metalness 0
          }
          geometry Box {
            size 0.01 0.07 0.005
          }
        }
        SliderJoint {
          jointParameters JointParameters {
            axis 0 1 0
          }
          device [
            LinearMotor {
              name "camera_slider"
            }
          ]
          endPoint Solid {
            translation 0 -0.025 0
            children [
              HingeJoint {
                jointParameters HingeJointParameters {
                  axis 0 1 0
                }
                device [
                  RotationalMotor {
                    name "camera_servo_y"
                  }
                ]
                endPoint Solid {
                  children [
                    HingeJoint {
                      jointParameters HingeJointParameters {
                        axis 0 1 0
                        anchor 0 0 -0.0525
                      }
                      device [
                        RotationalMotor {
                          name "surface_slider"
                        }
                      ]
                      endPoint Solid {
                        children [
                          HingeJoint {
                            jointParameters HingeJointParameters {
                            }
                            device [
                              RotationalMotor {
                                name "camera_servo_x"
                              }
                            ]
                            endPoint Solid {
                              rotation 1 0 0 0
                              children [
                                Shape {
                                  appearance PBRAppearance {
                                  }
                                  geometry Box {
                                    size 0.005 0.005 0.005
                                  }
                                }
                                Camera {
                                  translation 0 0 0.0025
                                  rotation 1.834929511093189e-09 0.9238797538373538 0.38268289803626016 3.14159
                                  fieldOfView 1.57
                                  spherical TRUE
                                }
                              ]
                            }
                          }
                        ]
                        name "solid(1)"
                      }
                    }
                  ]
                }
              }
            ]
            name "solid(3)"
          }
        }
      ]
    }
  ]
  name "robot1"
  boundingObject USE body
  physics Physics {
  }
  controller "Bitfinit_MainCode"
}
